#VRML_SIM R2023b utf8
# license: Apache License 2.0
# license url: http://www.apache.org/licenses/LICENSE-2.0
# This is a proto file for Webots for the dog_asm
# Extracted from: urdf/dog_asm.urdf

PROTO dog_asm [
  field  SFVec3f     translation     0 0 0
  field  SFRotation  rotation        0 0 1 0
  field  SFString    name            "dog_asm"  # Is `Robot.name`.
  field  SFString    controller      "void"     # Is `Robot.controller`.
  field  MFString    controllerArgs  []         # Is `Robot.controllerArgs`.
  field  SFString    customData      ""         # Is `Robot.customData`.
  field  SFBool      supervisor      FALSE      # Is `Robot.supervisor`.
  field  SFBool      synchronization TRUE       # Is `Robot.synchronization`.
  field  SFBool      selfCollision   TRUE       # Is `Robot.selfCollision`.
]
{
  Robot {
    translation IS translation
    rotation IS rotation
    controller IS controller
    controllerArgs IS controllerArgs
    customData IS customData
    supervisor IS supervisor
    synchronization IS synchronization
    selfCollision IS selfCollision
    children [
      Shape {
        appearance DEF base_link_material PBRAppearance {
          baseColor 1.000000 0.844610 0.620030
          roughness 1.000000
          metalness 0
        }
        geometry DEF base_link Mesh {
          url "meshes/base_link.STL"
        }
      }
      HingeJoint {
        jointParameters HingeJointParameters {
          axis 1.000000 0.000000 -0.000000
          anchor 0.296530 0.090000 0.045000
        }
        device [
          RotationalMotor {
            name "JShoulderLF"
            maxTorque 10000
          }
          PositionSensor {
            name "JShoulderLF_sensor"
          }
        ]
        endPoint Solid {
          translation 0.296530 0.090000 0.045000
          rotation 0.600762 0.527419 0.600762 2.170916
          children [
            Shape {
              appearance DEF ShoulderLF_material PBRAppearance {
                baseColor 0.819610 0.701960 0.431370
                roughness 1.000000
                metalness 0
              }
              geometry DEF ShoulderLF Mesh {
                url "meshes/ShoulderLF.STL"
              }
            }
            HingeJoint {
              jointParameters HingeJointParameters {
                axis 1.000000 -0.000000 -0.000000
                anchor 0.140000 0.000000 0.000000
              }
              device [
                RotationalMotor {
                  name "JLegUpLF"
                  maxTorque 10000
                }
                PositionSensor {
                  name "JLegUpLF_sensor"
                }
              ]
              endPoint Solid {
                translation 0.140000 0.000000 0.000000
                rotation -0.304103 0.902797 -0.304103 1.672878
                children [
                  Shape {
                    appearance DEF LegUpLF_material PBRAppearance {
                      baseColor 0.803922 0.584314 0.192157
                      roughness 1.000000
                      metalness 0
                    }
                    geometry DEF LegUpLF Mesh {
                      url "meshes/LegUpLF.STL"
                    }
                  }
                  HingeJoint {
                    jointParameters HingeJointParameters {
                      axis 0.000000 -0.000000 1.000000
                      anchor 0.330000 0.000000 -0.035000
                    }
                    device [
                      RotationalMotor {
                        name "JLegDownLF"
                        maxTorque 10000
                      }
                      PositionSensor {
                        name "JLegDownLF_sensor"
                      }
                    ]
                    endPoint Solid {
                      translation 0.330000 0.000000 -0.035000
                      rotation 0.000000 0.000000 -1.000000 2.466600
                      children [
                        Shape {
                          appearance DEF LegDownLF_material PBRAppearance {
                            baseColor 0.819608 0.701961 0.431373
                            roughness 1.000000
                            metalness 0
                          }
                          geometry DEF LegDownLF Mesh {
                            url "meshes/LegDownLF.STL"
                          }
                        }
                        HingeJoint {
                          jointParameters HingeJointParameters {
                            axis 0.000000 0.000000 1.000000
                            anchor 0.330000 0.000000 0.008000
                          }
                          device [
                            RotationalMotor {
                              name "JWheelLF"
                              maxTorque 10000
                            }
                            PositionSensor {
                              name "JWheelLF_sensor"
                            }
                          ]
                          endPoint Solid {
                            translation 0.330000 0.000000 0.008000
                            children [
                              Shape {
                                appearance DEF WheelLF_material PBRAppearance {
                                  baseColor 0.803922 0.584314 0.192157
                                  roughness 1.000000
                                  metalness 0
                                }
                                geometry DEF WheelLF Mesh {
                                  url "meshes/WheelLF.STL"
                                }
                              }
                            ]
                            name "WheelLF"
                            boundingObject USE WheelLF
                            physics Physics {
                              density -1
                              mass 0.327511
                              centerOfMass [ 0.000000 0.000000 0.015169 ]
                              inertiaMatrix [
                                5.105612e-04 5.105612e-04 9.778591e-04
                                -9.317362e-21 4.764560e-21 2.710505e-20
                              ]
                            }
                          }
                        }
                      ]
                      name "LegDownLF"
                      boundingObject USE LegDownLF
                      physics Physics {
                        density -1
                        mass 1.051698
                        centerOfMass [ 0.165077 0.000000 -0.014832 ]
                        inertiaMatrix [
                          4.951673e-04 1.697934e-02 1.711921e-02
                          5.334047e-09 -3.704314e-05 -8.270786e-12
                        ]
                      }
                    }
                  }
                ]
                name "LegUpLF"
                boundingObject USE LegUpLF
                physics Physics {
                  density -1
                  mass 1.801531
                  centerOfMass [ 0.140259 -0.000000 -0.049588 ]
                  inertiaMatrix [
                    1.856066e-03 2.539860e-02 2.454030e-02
                    2.321361e-10 1.041004e-04 2.082933e-11
                  ]
                }
              }
            }
          ]
          name "ShoulderLF"
          boundingObject USE ShoulderLF
          physics Physics {
            density -1
            mass 0.713240
            centerOfMass [ 0.001635 -0.000000 0.000941 ]
            inertiaMatrix [
              1.027200e-03 9.852400e-04 8.053200e-04
              7.786500e-09 1.097000e-06 -2.021700e-09
            ]
          }
        }
      }
      HingeJoint {
        jointParameters HingeJointParameters {
          axis 1.000000 -0.000000 -0.000000
          anchor 0.296530 -0.090000 0.045000
        }
        device [
          RotationalMotor {
            name "JShoulderRF"
            maxTorque 10000
          }
          PositionSensor {
            name "JShoulderRF_sensor"
          }
        ]
        endPoint Solid {
          translation 0.296530 -0.090000 0.045000
          rotation -0.576737 0.578576 -0.576737 2.092564
          children [
            Shape {
              appearance DEF ShoulderRF_material PBRAppearance {
                baseColor 0.819610 0.701960 0.431370
                roughness 1.000000
                metalness 0
              }
              geometry DEF ShoulderRF Mesh {
                url "meshes/ShoulderRF.STL"
              }
            }
            HingeJoint {
              jointParameters HingeJointParameters {
                axis 1.000000 0.000000 -0.000000
                anchor 0.120000 0.000000 0.000000
              }
              device [
                RotationalMotor {
                  name "JLegUpRF"
                  maxTorque 10000
                }
                PositionSensor {
                  name "JLegUpRF_sensor"
                }
              ]
              endPoint Solid {
                translation 0.120000 0.000000 0.000000
                rotation 0.391042 0.833170 0.391042 1.752313
                children [
                  Shape {
                    appearance DEF LegUpRF_material PBRAppearance {
                      baseColor 0.803920 0.584310 0.192160
                      roughness 1.000000
                      metalness 0
                    }
                    geometry DEF LegUpRF Mesh {
                      url "meshes/LegUpRF.STL"
                    }
                  }
                  HingeJoint {
                    jointParameters HingeJointParameters {
                      axis 0.000000 0.000000 1.000000
                      anchor 0.330000 0.000000 -0.015000
                    }
                    device [
                      RotationalMotor {
                        name "JLegDownRF"
                        maxTorque 10000
                      }
                      PositionSensor {
                        name "JLegDownRF_sensor"
                      }
                    ]
                    endPoint Solid {
                      translation 0.330000 0.000000 -0.015000
                      rotation 0.000000 0.000000 1.000000 1.924200
                      children [
                        Shape {
                          appearance DEF LegDownRF_material PBRAppearance {
                            baseColor 0.819610 0.701960 0.431370
                            roughness 1.000000
                            metalness 0
                          }
                          geometry DEF LegDownRF Mesh {
                            url "meshes/LegDownRF.STL"
                          }
                        }
                        HingeJoint {
                          jointParameters HingeJointParameters {
                            axis 0.000000 0.000000 1.000000
                            anchor 0.330000 0.000000 0.008000
                          }
                          device [
                            RotationalMotor {
                              name "JWheelRF"
                              maxTorque 10000
                            }
                            PositionSensor {
                              name "JWheelRF_sensor"
                            }
                          ]
                          endPoint Solid {
                            translation 0.330000 0.000000 0.008000
                            children [
                              Shape {
                                appearance DEF WheelRF_material PBRAppearance {
                                  baseColor 0.803920 0.584310 0.192160
                                  roughness 1.000000
                                  metalness 0
                                }
                                geometry DEF WheelRF Mesh {
                                  url "meshes/WheelRF.STL"
                                }
                              }
                            ]
                            name "WheelRF"
                            boundingObject USE WheelRF
                            physics Physics {
                              density -1
                              mass 0.327510
                              centerOfMass [ -0.000000 0.000000 0.015169 ]
                              inertiaMatrix [
                                5.105600e-04 5.105600e-04 9.778600e-04
                                2.710500e-19 -1.508800e-20 -1.312900e-20
                              ]
                            }
                          }
                        }
                      ]
                      name "LegDownRF"
                      boundingObject USE LegDownRF
                      physics Physics {
                        density -1
                        mass 1.051700
                        centerOfMass [ 0.165080 0.000000 -0.014832 ]
                        inertiaMatrix [
                          4.951700e-04 1.697900e-02 1.711900e-02
                          5.345100e-09 -3.704300e-05 -1.244800e-11
                        ]
                      }
                    }
                  }
                ]
                name "LegUpRF"
                boundingObject USE LegUpRF
                physics Physics {
                  density -1
                  mass 1.801500
                  centerOfMass [ 0.140260 -0.000000 -0.029588 ]
                  inertiaMatrix [
                    1.856100e-03 2.539900e-02 2.454000e-02
                    2.321400e-10 1.041000e-04 2.082900e-11
                  ]
                }
              }
            }
          ]
          name "ShoulderRF"
          boundingObject USE ShoulderRF
          physics Physics {
            density -1
            mass 0.713240
            centerOfMass [ 0.001635 -0.000000 0.000941 ]
            inertiaMatrix [
              1.027100e-03 9.852100e-04 8.053000e-04
              3.861600e-10 1.097700e-06 -5.255300e-10
            ]
          }
        }
      }
      HingeJoint {
        jointParameters HingeJointParameters {
          axis -1.000000 -0.000000 -0.000000
          anchor -0.296530 0.090000 0.045000
        }
        device [
          RotationalMotor {
            name "JShoulderLB"
            maxTorque 10000
          }
          PositionSensor {
            name "JShoulderLB_sensor"
          }
        ]
        endPoint Solid {
          translation -0.296530 0.090000 0.045000
          rotation -0.574842 -0.582335 0.574842 2.086940
          children [
            Shape {
              appearance DEF ShoulderLB_material PBRAppearance {
                baseColor 0.819610 0.701960 0.431370
                roughness 1.000000
                metalness 0
              }
              geometry DEF ShoulderLB Mesh {
                url "meshes/ShoulderLB.STL"
              }
            }
            HingeJoint {
              jointParameters HingeJointParameters {
                axis 1.000000 0.000000 -0.000000
                anchor 0.120000 0.000000 0.000000
              }
              device [
                RotationalMotor {
                  name "JLegUpLB"
                  maxTorque 10000
                }
                PositionSensor {
                  name "JLegUpLB_sensor"
                }
              ]
              endPoint Solid {
                translation 0.120000 0.000000 0.000000
                rotation 0.691516 0.208835 0.691516 2.729851
                children [
                  Shape {
                    appearance DEF LegUpLB_material PBRAppearance {
                      baseColor 0.803920 0.584310 0.192160
                      roughness 1.000000
                      metalness 0
                    }
                    geometry DEF LegUpLB Mesh {
                      url "meshes/LegUpLB.STL"
                    }
                  }
                  HingeJoint {
                    jointParameters HingeJointParameters {
                      axis 0.000000 -0.000000 1.000000
                      anchor 0.330000 0.000000 -0.015000
                    }
                    device [
                      RotationalMotor {
                        name "JLegDownLB"
                        maxTorque 10000
                      }
                      PositionSensor {
                        name "JLegDownLB_sensor"
                      }
                    ]
                    endPoint Solid {
                      translation 0.330000 0.000000 -0.015000
                      rotation 0.000000 0.000000 -1.000000 2.376100
                      children [
                        Shape {
                          appearance DEF LegDownLB_material PBRAppearance {
                            baseColor 0.819610 0.701960 0.431370
                            roughness 1.000000
                            metalness 0
                          }
                          geometry DEF LegDownLB Mesh {
                            url "meshes/LegDownLB.STL"
                          }
                        }
                        HingeJoint {
                          jointParameters HingeJointParameters {
                            axis 0.000000 0.000000 1.000000
                            anchor 0.330000 0.000000 0.008000
                          }
                          device [
                            RotationalMotor {
                              name "JWheelLB"
                              maxTorque 10000
                            }
                            PositionSensor {
                              name "JWheelLB_sensor"
                            }
                          ]
                          endPoint Solid {
                            translation 0.330000 0.000000 0.008000
                            children [
                              Shape {
                                appearance DEF WheelLB_material PBRAppearance {
                                  baseColor 0.803920 0.584310 0.192160
                                  roughness 1.000000
                                  metalness 0
                                }
                                geometry DEF WheelLB Mesh {
                                  url "meshes/WheelLB.STL"
                                }
                              }
                            ]
                            name "WheelLB"
                            boundingObject USE WheelLB
                            physics Physics {
                              density -1
                              mass 0.327510
                              centerOfMass [ 0.000000 0.000000 0.015169 ]
                              inertiaMatrix [
                                5.105600e-04 5.105600e-04 9.778600e-04
                                6.776300e-21 -9.211500e-21 2.964600e-21
                              ]
                            }
                          }
                        }
                      ]
                      name "LegDownLB"
                      boundingObject USE LegDownLB
                      physics Physics {
                        density -1
                        mass 1.051700
                        centerOfMass [ 0.165080 0.000000 -0.014832 ]
                        inertiaMatrix [
                          4.951700e-04 1.697900e-02 1.711900e-02
                          5.344300e-09 -3.704300e-05 -1.217200e-11
                        ]
                      }
                    }
                  }
                ]
                name "LegUpLB"
                boundingObject USE LegUpLB
                physics Physics {
                  density -1
                  mass 1.801500
                  centerOfMass [ 0.140260 -0.000000 -0.029588 ]
                  inertiaMatrix [
                    1.856100e-03 2.539900e-02 2.454000e-02
                    2.321400e-10 1.041000e-04 2.082900e-11
                  ]
                }
              }
            }
          ]
          name "ShoulderLB"
          boundingObject USE ShoulderLB
          physics Physics {
            density -1
            mass 0.713240
            centerOfMass [ 0.001635 -0.000000 0.000941 ]
            inertiaMatrix [
              1.027100e-03 9.852100e-04 8.053000e-04
              3.836400e-10 1.097700e-06 -5.197500e-10
            ]
          }
        }
      }
      HingeJoint {
        jointParameters HingeJointParameters {
          axis -1.000000 0.000000 -0.000000
          anchor -0.296530 -0.090000 0.045000
        }
        device [
          RotationalMotor {
            name "JShoulderRB"
            maxTorque 10000
          }
          PositionSensor {
            name "JShoulderRB_sensor"
          }
        ]
        endPoint Solid {
          translation -0.296530 -0.090000 0.045000
          rotation 0.592648 -0.545469 -0.592648 2.142884
          children [
            Shape {
              appearance DEF ShoulderRB_material PBRAppearance {
                baseColor 0.819610 0.701960 0.431370
                roughness 1.000000
                metalness 0
              }
              geometry DEF ShoulderRB Mesh {
                url "meshes/ShoulderRB.STL"
              }
            }
            HingeJoint {
              jointParameters HingeJointParameters {
                axis 1.000000 -0.000000 -0.000000
                anchor 0.120000 0.000000 0.000000
              }
              device [
                RotationalMotor {
                  name "JLegUpRB"
                  maxTorque 10000
                }
                PositionSensor {
                  name "JLegUpRB_sensor"
                }
              ]
              endPoint Solid {
                translation 0.120000 0.000000 0.000000
                rotation -0.687332 0.234842 -0.687332 2.680278
                children [
                  Shape {
                    appearance DEF LegUpRB_material PBRAppearance {
                      baseColor 0.803920 0.584310 0.192160
                      roughness 1.000000
                      metalness 0
                    }
                    geometry DEF LegUpRB Mesh {
                      url "meshes/LegUpRB.STL"
                    }
                  }
                  HingeJoint {
                    jointParameters HingeJointParameters {
                      axis 0.000000 0.000000 1.000000
                      anchor 0.330000 0.000000 -0.015000
                    }
                    device [
                      RotationalMotor {
                        name "JLegDownRB"
                        maxTorque 10000
                      }
                      PositionSensor {
                        name "JLegDownRB_sensor"
                      }
                    ]
                    endPoint Solid {
                      translation 0.330000 0.000000 -0.015000
                      rotation 0.000000 0.000000 1.000000 2.104100
                      children [
                        Shape {
                          appearance DEF LegDownRB_material PBRAppearance {
                            baseColor 0.819610 0.701960 0.431370
                            roughness 1.000000
                            metalness 0
                          }
                          geometry DEF LegDownRB Mesh {
                            url "meshes/LegDownRB.STL"
                          }
                        }
                        HingeJoint {
                          jointParameters HingeJointParameters {
                            axis 0.000000 0.000000 1.000000
                            anchor 0.330000 0.000000 0.008000
                          }
                          device [
                            RotationalMotor {
                              name "JWheelRB"
                              maxTorque 10000
                            }
                            PositionSensor {
                              name "JWheelRB_sensor"
                            }
                          ]
                          endPoint Solid {
                            translation 0.330000 0.000000 0.008000
                            children [
                              Shape {
                                appearance DEF WheelRB_material PBRAppearance {
                                  baseColor 0.803920 0.584310 0.192160
                                  roughness 1.000000
                                  metalness 0
                                }
                                geometry DEF WheelRB Mesh {
                                  url "meshes/WheelRB.STL"
                                }
                              }
                            ]
                            name "WheelRB"
                            boundingObject USE WheelRB
                            physics Physics {
                              density -1
                              mass 0.327510
                              centerOfMass [ 0.000000 0.000000 0.015169 ]
                              inertiaMatrix [
                                5.105600e-04 5.105600e-04 9.778600e-04
                                -2.710500e-19 -8.470300e-21 1.355300e-20
                              ]
                            }
                          }
                        }
                      ]
                      name "LegDownRB"
                      boundingObject USE LegDownRB
                      physics Physics {
                        density -1
                        mass 1.051700
                        centerOfMass [ 0.165080 0.000000 -0.014832 ]
                        inertiaMatrix [
                          4.951700e-04 1.697900e-02 1.711900e-02
                          5.320400e-09 -3.704300e-05 -1.037300e-11
                        ]
                      }
                    }
                  }
                ]
                name "LegUpRB"
                boundingObject USE LegUpRB
                physics Physics {
                  density -1
                  mass 1.801500
                  centerOfMass [ 0.140260 -0.000000 -0.029588 ]
                  inertiaMatrix [
                    1.856100e-03 2.539900e-02 2.454000e-02
                    2.321400e-10 1.041000e-04 2.082900e-11
                  ]
                }
              }
            }
          ]
          name "ShoulderRB"
          boundingObject USE ShoulderRB
          physics Physics {
            density -1
            mass 0.713250
            centerOfMass [ 0.001635 0.000000 0.000941 ]
            inertiaMatrix [
              1.027100e-03 9.852100e-04 8.053000e-04
              3.722600e-10 1.097600e-06 -4.612800e-10
            ]
          }
        }
      }
    ]
    name IS name
    boundingObject USE base_link
    physics Physics {
      density -1
      mass 15.156000
      centerOfMass [ 0.001380 0.000000 0.023473 ]
      inertiaMatrix [
        9.408200e-02 3.346500e-01 3.879500e-01
        -2.657100e-07 -1.564800e-03 4.409700e-09
      ]
    }
  }
}
