#VRML_SIM R2023b utf8
# license: Apache License 2.0
# license url: http://www.apache.org/licenses/LICENSE-2.0
# This is a proto file for Webots for the dog_asm2
# Extracted from: E:\APPData\WebotDoc\Dogtest\DogURDF\dog_asm2\urdf\dog_asm2.urdf

PROTO dog_asm2 [
  field  SFVec3f     translation     0 0 0
  field  SFRotation  rotation        0 0 1 0
  field  SFString    name            "dog_asm2"  # Is `Robot.name`.
  field  SFString    controller      "void"      # Is `Robot.controller`.
  field  MFString    controllerArgs  []          # Is `Robot.controllerArgs`.
  field  SFString    customData      ""          # Is `Robot.customData`.
  field  SFBool      supervisor      FALSE       # Is `Robot.supervisor`.
  field  SFBool      synchronization TRUE        # Is `Robot.synchronization`.
  field  SFBool      selfCollision   TRUE        # Is `Robot.selfCollision`.
]
{
  Robot {
    translation IS translation
    rotation IS rotation
    controller IS controller
    controllerArgs IS controllerArgs
    customData IS customData
    supervisor IS supervisor
    synchronization IS synchronization
    selfCollision IS selfCollision
    children [
      Shape {
        appearance DEF Body_material PBRAppearance {
          baseColor 0.792160 0.819610 0.933330
          roughness 1.000000
          metalness 0
        }
        geometry DEF Body Mesh {
          url "meshes/Body.STL"
        }
      }
      HingeJoint {
        jointParameters HingeJointParameters {
          # axis -1.000000 0.000000 -0.000000
          axis 1.000000 0.000000 -0.000000
          anchor 0.296530 0.090000 0.045000
        }
        device [
          RotationalMotor {
            name "JShoulderLF"
            maxTorque 10000
            maxPosition 1.57080
            minPosition -0.34906
          }
          PositionSensor {
            name "JShoulderLF_sensor"
          }
        ]
        endPoint Solid {
          translation 0.296530 0.090000 0.045000
          # rotation 0.000000 -1.000000 0.000000 1.570800
          rotation 0.707108 0.000000 0.707108 3.141592
          children [
            Shape {
              appearance DEF ShoulderLF_material PBRAppearance {
                baseColor 0.792160 0.819610 0.933330
                roughness 1.000000
                metalness 0
              }
              geometry DEF ShoulderLF Mesh {
                url "meshes/ShoulderLF.STL"
              }
            }
            HingeJoint {
              jointParameters HingeJointParameters {
                axis 0.000000 -1.000000 -0.000000
                anchor 0.000000 -0.140000 0.000000
              }
              device [
                RotationalMotor {
                  name "JLegUpLF"
                  maxTorque 10000
                  maxPosition 3.14159
                  minPosition -3.14158
                }
                PositionSensor {
                  name "JLegUpLF_sensor"
                }
              ]
              endPoint Solid {
                translation 0.000000 -0.140000 0.000000
                rotation 0.000003 -0.707108 0.707105 3.141598
                children [
                  Shape {
                    appearance DEF LegUpLF_material PBRAppearance {
                      baseColor 0.792160 0.819610 0.933330
                      roughness 1.000000
                      metalness 0
                    }
                    geometry DEF LegUpLF Mesh {
                      url "meshes/LegUpLF.STL"
                    }
                  }
                  HingeJoint {
                    jointParameters HingeJointParameters {
                      axis 0.000000 0.000000 1.000000
                      anchor 0.330000 0.000000 -0.035000
                    }
                    device [
                      RotationalMotor {
                        name "JLegDownLF"
                        maxTorque 10000
                        maxPosition 2.61800
                        minPosition -2.61800
                      }
                      PositionSensor {
                        name "JLegDownLF_sensor"
                      }
                    ]
                    endPoint Solid {
                      translation 0.330000 0.000000 -0.035000
                      children [
                        Shape {
                          appearance DEF LegDownLF_material PBRAppearance {
                            baseColor 0.792160 0.819610 0.933330
                            roughness 1.000000
                            metalness 0
                          }
                          geometry DEF LegDownLF Mesh {
                            url "meshes/LegDownLF.STL"
                          }
                        }
                        HingeJoint {
                          jointParameters HingeJointParameters {
                            axis 0.000000 0.000000 1.000000
                            anchor 0.330000 0.000000 0.008000
                          }
                          device [
                            RotationalMotor {
                              name "JWheelLF"
                              maxTorque 10000
                            }
                            PositionSensor {
                              name "JWheelLF_sensor"
                            }
                          ]
                          endPoint Solid {
                            translation 0.330000 0.000000 0.008000
                            children [
                              Shape {
                                appearance DEF WheelLF_material PBRAppearance {
                                  baseColor 0.792160 0.819610 0.933330
                                  roughness 1.000000
                                  metalness 0
                                }
                                geometry DEF WheelLF Mesh {
                                  url "meshes/WheelLF.STL"
                                }
                              }
                            ]
                            name "WheelLF"
                            boundingObject USE WheelLF
                            physics Physics {
                              density -1
                              mass 0.327510
                              centerOfMass [ -0.000000 0.000000 0.015169 ]
                              inertiaMatrix [
                                5.105600e-04 5.105600e-04 9.778600e-04
                                -2.283000e-21 -8.891100e-21 -6.918000e-22
                              ]
                            }
                          }
                        }
                      ]
                      name "LegDownLF"
                      boundingObject USE LegDownLF
                      physics Physics {
                        density -1
                        mass 1.051700
                        centerOfMass [ 0.165080 0.000000 -0.014832 ]
                        inertiaMatrix [
                          4.951700e-04 1.697900e-02 1.711900e-02
                          5.345300e-09 -3.704300e-05 -1.256600e-11
                        ]
                      }
                    }
                  }
                ]
                name "LegUpLF"
                boundingObject USE LegUpLF
                physics Physics {
                  density -1
                  mass 1.801500
                  centerOfMass [ 0.140260 -0.000000 -0.049588 ]
                  inertiaMatrix [
                    1.856100e-03 2.539900e-02 2.454000e-02
                    2.321400e-10 1.041000e-04 2.082900e-11
                  ]
                }
              }
            }
          ]
          name "ShoulderLF"
          boundingObject USE ShoulderLF
          physics Physics {
            density -1
            mass 0.713240
            centerOfMass [ -0.000000 -0.001635 0.000941 ]
            inertiaMatrix [
              9.852100e-04 1.027100e-03 8.053000e-04
              -3.857000e-10 -5.274300e-10 -1.097700e-06
            ]
          }
        }
      }
      HingeJoint {
        jointParameters HingeJointParameters {
          axis 1.000000 0.000000 -0.000000
          anchor 0.296530 -0.090000 0.045000
        }
        device [
          RotationalMotor {
            name "JShoulderRF"
            maxTorque 10000
            maxPosition 0.34906
            minPosition -1.57080
          }
          PositionSensor {
            name "JShoulderRF_sensor"
          }
        ]
        endPoint Solid {
          translation 0.296530 -0.090000 0.045000
          rotation 0.000000 1.000000 0.000000 1.570800
          children [
            Shape {
              appearance DEF ShoulderRF_material PBRAppearance {
                baseColor 0.792160 0.819610 0.933330
                roughness 1.000000
                metalness 0
              }
              geometry DEF ShoulderRF Mesh {
                url "meshes/ShoulderRF.STL"
              }
            }
            HingeJoint {
              jointParameters HingeJointParameters {
                axis 0.000000 -1.000000 -0.000000
                anchor 0.000000 -0.140000 0.000000
              }
              device [
                RotationalMotor {
                  name "JLegUpRF"
                  maxTorque 10000
                  maxPosition 3.14159
                  minPosition -3.14158
                }
                PositionSensor {
                  name "JLegUpRF_sensor"
                }
              ]
              endPoint Solid {
                translation 0.000000 -0.140000 0.000000
                # rotation 0.000003 -0.707108 0.707105 3.141598
                rotation 1.000000 0.000000 0.000000 1.570800
                children [
                  Shape {
                    appearance DEF LegUpRF_material PBRAppearance {
                      baseColor 0.792160 0.819610 0.933330
                      roughness 1.000000
                      metalness 0
                    }
                    geometry DEF LegUpRF Mesh {
                      url "meshes/LegUpRF.STL"
                    }
                  }
                  HingeJoint {
                    jointParameters HingeJointParameters {
                      axis 0.000000 0.000000 1.000000
                      anchor 0.330000 0.000000 -0.035000
                    }
                    device [
                      RotationalMotor {
                        name "JLegDownRF"
                        maxTorque 10000
                        maxPosition 2.61800
                        minPosition -2.61800
                      }
                      PositionSensor {
                        name "JLegDownRF_sensor"
                      }
                    ]
                    endPoint Solid {
                      translation 0.330000 0.000000 -0.035000
                      children [
                        Shape {
                          appearance DEF LegDownRF_material PBRAppearance {
                            baseColor 0.792160 0.819610 0.933330
                            roughness 1.000000
                            metalness 0
                          }
                          geometry DEF LegDownRF Mesh {
                            url "meshes/LegDownRF.STL"
                          }
                        }
                        HingeJoint {
                          jointParameters HingeJointParameters {
                            axis 0.000000 0.000000 1.000000
                            anchor 0.330000 0.000000 0.008000
                          }
                          device [
                            RotationalMotor {
                              name "JWheelRF"
                              maxTorque 10000
                            }
                            PositionSensor {
                              name "JWheelRF_sensor"
                            }
                          ]
                          endPoint Solid {
                            translation 0.330000 0.000000 0.008000
                            children [
                              Shape {
                                appearance DEF WheelRF_material PBRAppearance {
                                  baseColor 0.792160 0.819610 0.933330
                                  roughness 1.000000
                                  metalness 0
                                }
                                geometry DEF WheelRF Mesh {
                                  url "meshes/WheelRF.STL"
                                }
                              }
                            ]
                            name "WheelRF"
                            boundingObject USE WheelRF
                            physics Physics {
                              density -1
                              mass 0.327510
                              centerOfMass [ 0.000000 0.000000 0.015169 ]
                              inertiaMatrix [
                                5.105600e-04 5.105600e-04 9.778600e-04
                                -3.213600e-21 -8.891100e-21 -6.430800e-22
                              ]
                            }
                          }
                        }
                      ]
                      name "LegDownRF"
                      boundingObject USE LegDownRF
                      physics Physics {
                        density -1
                        mass 1.051700
                        centerOfMass [ 0.165080 0.000000 -0.014832 ]
                        inertiaMatrix [
                          4.951700e-04 1.697900e-02 1.711900e-02
                          5.345300e-09 -3.704300e-05 -1.256600e-11
                        ]
                      }
                    }
                  }
                ]
                name "LegUpRF"
                boundingObject USE LegUpRF
                physics Physics {
                  density -1
                  mass 1.801500
                  centerOfMass [ 0.140260 -0.000000 -0.049588 ]
                  inertiaMatrix [
                    1.856100e-03 2.539900e-02 2.454000e-02
                    2.321400e-10 1.041000e-04 2.082900e-11
                  ]
                }
              }
            }
          ]
          name "ShoulderRF"
          boundingObject USE ShoulderRF
          physics Physics {
            density -1
            mass 0.713240
            centerOfMass [ -0.000000 -0.001635 0.000941 ]
            inertiaMatrix [
              9.852100e-04 1.027100e-03 8.053000e-04
              -3.857000e-10 -5.274300e-10 -1.097700e-06
            ]
          }
        }
      }
      HingeJoint {
        jointParameters HingeJointParameters {
          axis -1.000000 0.000000 0.000000
          anchor -0.296530 0.090000 0.045000
        }
        device [
          RotationalMotor {
            name "JShoulderLB"
            maxTorque 10000
            maxPosition 0.34906
            minPosition -1.57080
          }
          PositionSensor {
            name "JShoulderLB_sensor"
          }
        ]
        endPoint Solid {
          translation -0.296530 0.090000 0.045000
          rotation 0.707105 -0.000003 -0.707108 3.141598
          children [
            Shape {
              appearance DEF ShoulderLB_material PBRAppearance {
                baseColor 0.792160 0.819610 0.933330
                roughness 1.000000
                metalness 0
              }
              geometry DEF ShoulderLB Mesh {
                url "meshes/ShoulderLB.STL"
              }
            }
            HingeJoint {
              jointParameters HingeJointParameters {
                axis 0.000000 -1.000000 -0.000000
                anchor 0.000000 -0.140000 0.000000
              }
              device [
                RotationalMotor {
                  name "JLegUpLB"
                  maxTorque 10000
                  maxPosition 3.14159
                  minPosition -3.14158
                }
                PositionSensor {
                  name "JLegUpLB_sensor"
                }
              ]
              endPoint Solid {
                translation 0.000000 -0.140000 0.000000
                rotation 1.000000 0.000000 0.000000 1.570800
                children [
                  Shape {
                    appearance DEF LegUpLB_material PBRAppearance {
                      baseColor 0.792160 0.819610 0.933330
                      roughness 1.000000
                      metalness 0
                    }
                    geometry DEF LegUpLB Mesh {
                      url "meshes/LegUpLB.STL"
                    }
                  }
                  HingeJoint {
                    jointParameters HingeJointParameters {
                      axis 0.000000 0.000000 1.000000
                      anchor 0.330000 0.000000 -0.035000
                    }
                    device [
                      RotationalMotor {
                        name "JLegDownLB"
                        maxTorque 10000
                        maxPosition 2.61800
                        minPosition -2.61800
                      }
                      PositionSensor {
                        name "JLegDownLB_sensor"
                      }
                    ]
                    endPoint Solid {
                      translation 0.330000 0.000000 -0.035000
                      children [
                        Shape {
                          appearance DEF LegDownLB_material PBRAppearance {
                            baseColor 0.792160 0.819610 0.933330
                            roughness 1.000000
                            metalness 0
                          }
                          geometry DEF LegDownLB Mesh {
                            url "meshes/LegDownLB.STL"
                          }
                        }
                        HingeJoint {
                          jointParameters HingeJointParameters {
                            axis 0.000000 0.000000 1.000000
                            anchor 0.330000 0.000000 0.008000
                          }
                          device [
                            RotationalMotor {
                              name "JWheelLB"
                              maxTorque 10000
                            }
                            PositionSensor {
                              name "JWheelLB_sensor"
                            }
                          ]
                          endPoint Solid {
                            translation 0.330000 0.000000 0.008000
                            children [
                              Shape {
                                appearance DEF WheelLB_material PBRAppearance {
                                  baseColor 0.792160 0.819610 0.933330
                                  roughness 1.000000
                                  metalness 0
                                }
                                geometry DEF WheelLB Mesh {
                                  url "meshes/WheelLB.STL"
                                }
                              }
                            ]
                            name "WheelLB"
                            boundingObject USE WheelLB
                            physics Physics {
                              density -1
                              mass 0.327510
                              centerOfMass [ 0.000000 0.000000 0.015169 ]
                              inertiaMatrix [
                                5.105600e-04 5.105600e-04 9.778600e-04
                                -5.385000e-21 -8.891100e-21 -7.230400e-22
                              ]
                            }
                          }
                        }
                      ]
                      name "LegDownLB"
                      boundingObject USE LegDownLB
                      physics Physics {
                        density -1
                        mass 1.051700
                        centerOfMass [ 0.165080 0.000000 -0.014832 ]
                        inertiaMatrix [
                          4.951700e-04 1.697900e-02 1.711900e-02
                          5.345300e-09 -3.704300e-05 -1.256600e-11
                        ]
                      }
                    }
                  }
                ]
                name "LegUpLB"
                boundingObject USE LegUpLB
                physics Physics {
                  density -1
                  mass 1.801500
                  centerOfMass [ 0.140260 -0.000000 -0.049588 ]
                  inertiaMatrix [
                    1.856100e-03 2.539900e-02 2.454000e-02
                    2.321400e-10 1.041000e-04 2.082900e-11
                  ]
                }
              }
            }
          ]
          name "ShoulderLB"
          boundingObject USE ShoulderLB
          physics Physics {
            density -1
            mass 0.713240
            centerOfMass [ -0.000000 -0.001635 0.000941 ]
            inertiaMatrix [
              9.852100e-04 1.027100e-03 8.053000e-04
              -3.857000e-10 -5.274300e-10 -1.097700e-06
            ]
          }
        }
      }
      HingeJoint {
        jointParameters HingeJointParameters {
          # axis 1.000000 0.000000 0.000000
          axis -1.000000 0.000000 0.000000
          anchor -0.296530 -0.090000 0.045000
        }
        device [
          RotationalMotor {
            name "JShoulderRB"
            maxTorque 10000
            maxPosition 1.57080
            minPosition -0.34906
          }
          PositionSensor {
            name "JShoulderRB_sensor"
          }
        ]
        endPoint Solid {
          translation -0.296530 -0.090000 0.045000
          # rotation 0.707105 0.000003 0.707108 3.141598
          rotation 0.000000 -1.000000 0.000000 1.570800
          children [
            Shape {
              appearance DEF ShoulderRB_material PBRAppearance {
                baseColor 0.792160 0.819610 0.933330
                roughness 1.000000
                metalness 0
              }
              geometry DEF ShoulderRB Mesh {
                url "meshes/ShoulderRB.STL"
              }
            }
            HingeJoint {
              jointParameters HingeJointParameters {
                axis 0.000000 -1.000000 -0.000000
                anchor 0.000000 -0.140000 0.000000
              }
              device [
                RotationalMotor {
                  name "JLegUpRB"
                  maxTorque 10000
                  maxPosition 3.14159
                  minPosition -3.14158
                }
                PositionSensor {
                  name "JLegUpRB_sensor"
                }
              ]
              endPoint Solid {
                translation 0.000000 -0.140000 0.000000
                rotation 0.000003 -0.707108 0.707105 3.141598
                children [
                  Shape {
                    appearance DEF LegUpRB_material PBRAppearance {
                      baseColor 0.792160 0.819610 0.933330
                      roughness 1.000000
                      metalness 0
                    }
                    geometry DEF LegUpRB Mesh {
                      url "meshes/LegUpRB.STL"
                    }
                  }
                  HingeJoint {
                    jointParameters HingeJointParameters {
                      axis 0.000000 0.000000 1.000000
                      anchor 0.330000 0.000000 -0.035000
                    }
                    device [
                      RotationalMotor {
                        name "JLegDownRB"
                        maxTorque 10000
                        maxPosition 2.61800
                        minPosition -2.61800
                      }
                      PositionSensor {
                        name "JLegDownRB_sensor"
                      }
                    ]
                    endPoint Solid {
                      translation 0.330000 0.000000 -0.035000
                      children [
                        Shape {
                          appearance DEF LegDownRB_material PBRAppearance {
                            baseColor 0.792160 0.819610 0.933330
                            roughness 1.000000
                            metalness 0
                          }
                          geometry DEF LegDownRB Mesh {
                            url "meshes/LegDownRB.STL"
                          }
                        }
                        HingeJoint {
                          jointParameters HingeJointParameters {
                            axis 0.000000 0.000000 1.000000
                            anchor 0.330000 0.000000 0.008000
                          }
                          device [
                            RotationalMotor {
                              name "JWheelRB"
                              maxTorque 10000
                            }
                            PositionSensor {
                              name "JWheelRB_sensor"
                            }
                          ]
                          endPoint Solid {
                            translation 0.330000 0.000000 0.008000
                            children [
                              Shape {
                                appearance DEF WheelRB_material PBRAppearance {
                                  baseColor 0.792160 0.819610 0.933330
                                  roughness 1.000000
                                  metalness 0
                                }
                                geometry DEF WheelRB Mesh {
                                  url "meshes/WheelRB.STL"
                                }
                              }
                            ]
                            name "WheelRB"
                            boundingObject USE WheelRB
                            physics Physics {
                              density -1
                              mass 0.327510
                              centerOfMass [ -0.000000 0.000000 0.015169 ]
                              inertiaMatrix [
                                5.105600e-04 5.105600e-04 9.778600e-04
                                -6.522300e-21 -8.891100e-21 -6.755200e-22
                              ]
                            }
                          }
                        }
                      ]
                      name "LegDownRB"
                      boundingObject USE LegDownRB
                      physics Physics {
                        density -1
                        mass 1.051700
                        centerOfMass [ 0.165080 0.000000 -0.014832 ]
                        inertiaMatrix [
                          4.951700e-04 1.697900e-02 1.711900e-02
                          5.345300e-09 -3.704300e-05 -1.256600e-11
                        ]
                      }
                    }
                  }
                ]
                name "LegUpRB"
                boundingObject USE LegUpRB
                physics Physics {
                  density -1
                  mass 1.801500
                  centerOfMass [ 0.140260 -0.000000 -0.049588 ]
                  inertiaMatrix [
                    1.856100e-03 2.539900e-02 2.454000e-02
                    2.321400e-10 1.041000e-04 2.082900e-11
                  ]
                }
              }
            }
          ]
          name "ShoulderRB"
          boundingObject USE ShoulderRB
          physics Physics {
            density -1
            mass 0.713240
            centerOfMass [ -0.000000 -0.001635 0.000941 ]
            inertiaMatrix [
              9.852100e-04 1.027100e-03 8.053000e-04
              -3.857000e-10 -5.274300e-10 -1.097700e-06
            ]
          }
        }
      }
    ]
    name IS name
    boundingObject USE Body
    physics Physics {
      density -1
      mass 15.156000
      centerOfMass [ 0.001380 0.000000 0.023473 ]
      inertiaMatrix [
        9.408200e-02 3.346500e-01 3.879500e-01
        -2.657100e-07 -1.564800e-03 4.409700e-09
      ]
    }
  }
}
